Workbook

Sheet Página10
A1: Nome | B1: Turma | C1: Período | E1: Não Vai
A2: Aluno 047 | B2: Turma B1 | C2: Matutino | E2: Aluno (n/d) | F2: Turma | G2: O que fez ?
A3: Aluno 051 | B3: Turma B1 | C3: Matutino | E3: Aluno (n/d) | F3: B1 M | G3: Andando em cima da mureta mesmo após ser alertado
A4: Aluno 066 | B4: Turma B1 | C4: Matutino | E4: Aluno (n/d) | F4: D V | G4: Prática Anti-Desportiva
A5: Aluno 067 | B5: Turma B1 | C5: Matutino | E5: Aluno (n/d) | F5: D V | G5: Prática Anti-Desportiva
A6: Aluno 072 | B6: Turma B1 | C6: Matutino
A7: Aluno 075 | B7: Turma B1 | C7: Matutino
A8: Aluno 087 | B8: Turma B1 | C8: Matutino
A9: Aluno 133 | B9: Turma B1 | C9: Matutino
A10: Aluno 138 | B10: Turma B1 | C10: Matutino
A11: Aluno 127 | B11: Turma B1 | C11: Matutino
A12: Aluno 169 | B12: Turma B1 | C12: Matutino
A13: Aluno 224 | B13: Turma B1 | C13: Matutino
A14: Aluno 228 | B14: Turma B1 | C14: Matutino
A15: Aluno 020 | B15: Turma D | C15: Vespertino
A16: Aluno 040 | B16: Turma D | C16: Vespertino
A17: Aluno 048 | B17: Turma D | C17: Vespertino
... A45: Aluno 189 | B45: Turma E | C45: Matutino

Sheet Alunos
A1: Nome | B1: Turma | C1: Período | D1: Futebol | E1: Futsal | F1: Queimada | G1: Rouba Bandeira | H1: Basquete | I1: Vôlei | J1: Taekwondo | K1: Ginastica
A2: Aluno 001 | B2: Turma E | C2: Matutino | D2: Participa | E2: Participa | F2: Participa | G2: Participa | H2: Participa | I2: Participa | J2: Não Participa | K2: Não Participa
A3: Aluno 272 | B3: Turma C | C3: Matutino | D3: Não Participa | E3: Não Participa | F3: Não Participa | G3: Não Participa | H3: Não Participa | I3: Não Participa | J3: Não Participa | K3: Não Participa
A4: Aluno 002 | B4: Turma A | C4: Vespertino | D4: Não Participa | E4: Não Participa | F4: Não Participa | G4: Participa | H4: Não Participa | I4: Não Participa | J4: Participa | K4: Participa
A5: Aluno 273 | B5: Turma C | C5: Vespertino | D5: Não Participa | E5: Não Participa | F5: Não Participa | G5: Não Participa | H5: Não Participa | I5: Não Participa | J5: Não Participa | K5: Não Participa
A6: Aluno 003 | B6: Turma A | C6: Vespertino | D6: Não Participa | E6: Não Participa | F6: Não Participa | G6: Não Participa | H6: Não Participa | I6: Não Participa | J6: Não Participa | K6: Não Participa
A7: Aluno 274 | B7: Turma A | C7: Matutino | D7: Não Participa | E7: Não Participa | F7: Participa | G7: Participa | H7: Não Participa | I7: Não Participa | J7: Não Participa | K7: Participa
A8: Aluno 004 | B8: Turma B1 | C8: Vespertino | D8: Não Participa | E8: Não Participa | F8: Não Participa | G8: Não Participa | H8: Não Participa | I8: Não Participa | J8: Não Participa | K8: Não Participa
A9: Aluno 005 | B9: Turma B2 | C9: Vespertino | D9: Participa | E9: Participa | F9: Não Participa | G9: Não Participa | H9: Não Participa | I9: Não Participa | J9: Não Participa | K9: Não Participa
A10: Aluno 006 | B10: Turma E | C10: Vespertino | D10: Participa | E10: Participa | F10: Participa | G10: Participa | H10: Participa | I10: Participa | J10: Participa | K10: Não Participa
A11: Aluno 007 | B11: Turma B1 | C11: Vespertino | D11: Não Participa | E11: Não Participa | F11: Participa | G11: Participa | H11: Não Participa | I11: Não Participa | J11: Participa | K11: Participa
A12: Aluno 008 | B12: Turma C | C12: Matutino | D12: Participa | E12: Não Participa | F12: Participa | G12: Participa | H12: Não Participa | I12: Não Participa | J12: Participa | K12: Não Participa
... A276: Aluno 088 | B276: Turma GR | C276: Vespertino | D276: Participa | E276: Participa | F276: Participa | G276: Participa | H276: Participa | I276: Participa | J276: Não Participa | K276: Não Participa

Sheet Descontos
A1: Desconto de pontos
A2: Nome | B2: Turma | C2: O que fez ? | D2: Quantidade
A3: Aluno (n/d) | B3: B1 M | C3: Andando em cima da mureta mesmo após ser alertado | D3: 1
A4: Aluno (n/d) | B4: D V | C4: Prática Anti-Desportiva | D4: 2
A5: Aluno (n/d) | B5: D M | C5: Uso do equipamento sem autorização, Ameaça | D5: 4
A6: Aluno (n/d) | B6: D V | C6: Prática Anti-Desportiva | D6: 1
A7: Aluno 266 | B7: D M | C7: Sairam sem autorização e trouxeram itens de fora para fundação | D7: 2
A8: Aluno (n/d) | B8: D M | C8: Sairam sem autorização e trouxeram itens de fora para fundação | D8: 2
A9: Aluno (n/d) | B9: D M | C9: Sairam sem autorização e trouxeram itens de fora para fundação | D9: 2
A10: Aluno 084 | B10: C M | C10: Sairam sem autorização e trouxeram itens de fora para fundação | D10: 2
A11: Aluno (n/d) | B11: C M | C11: Sairam sem autorização e trouxeram itens de fora para fundação | D11: 2
A12: Aluno (n/d) | B12: B2 M | C12: Bagunça na linha do campo | D12: 1
A13: Aluno 183 | B13: B1 V | C13: Bagunça na linha do campo | D13: 1
A14: Aluno 267 | B14: D M | C14: Prática Anti-Desportiva | D14: 1
... A17: Aluno (n/d) | B17: Todos | C17: Trouxeram Telefone | D17: 1

Sheet Individual Taekwondo
A1: Competidores | B1: Turma | C1: Período | D1: Presente | E1: Categoria | F1: Sexo | H1: TAEKWONDO MIRIM MASCULINO | O1: TAEKWONDO MIRIM FEMININO | V1: TAEKWONDO INFANTIL MASCULINO | AC1: TAEKWONDO INFANTIL FEMININO | AJ1: TAEKWONDO CADETE MASCULINO | AQ1: TAEKWONDO CADETE FEMININO
A2: =IFERROR(__xludf.DUMMYFUNCTION("FILTER(Alunos!A:A, Alunos!J:J = ""Participa"")"),"AGATA LORRAINE ARAÚJO DA COSTA") | B2: =IFERROR(__xludf.DUMMYFUNCTION("FILTER(Alunos!B:B,Alunos!$J:$J = ""Participa"")"),"Turma A") | C2: =IFERROR(__xludf.DUMMYFUNCTION("FILTER(Alunos!C:C,Alunos!$J:$J = ""Participa"")"),"Vespertino") | D2: Veio | E2: MIRIM | F2: FEMININO
A3: =IFERROR(__xludf.DUMMYFUNCTION("""COMPUTED_VALUE"""),"ALLAN ALVES RIBEIRO") | B3: =IFERROR(__xludf.DUMMYFUNCTION("""COMPUTED_VALUE"""),"Turma E") | C3: =IFERROR(__xludf.DUMMYFUNCTION("""COMPUTED_VALUE"""),"Vespertino") | D3: Veio | E3: CADETE | F3: MASCULINO | H3: COLOCAÇÃO | I3: ALUNO | J3: Turma | K3: PONTOS | L3: PESO | O3: COLOCAÇÃO | P3: ALUNO | Q3: TURMA | R3: PONTOS | S3: PESO | V3: COLOCAÇÃO | W3: ALUNO | X3: TURMA | Y3: PONTOS | Z3: PESO | AC3: COLOCAÇÃO | AD3: ALUNO | AE3: TURMA | AF3: PONTOS | AG3: PESO | AJ3: COLOCAÇÃO | AK3: ALUNO | AL3: TURMA | AM3: PONTOS | AN3: PESO | AQ3: COLOCAÇÃO | AR3: ALUNO | AS3: TURMA | AT3: PONTOS | AU3: PESO
A4: =IFERROR(__xludf.DUMMYFUNCTION("""COMPUTED_VALUE"""),"ALLANA FERREIRA DA SILVA") | B4: =IFERROR(__xludf.DUMMYFUNCTION("""COMPUTED_VALUE"""),"Turma B1") | C4: =IFERROR(__xludf.DUMMYFUNCTION("""COMPUTED_VALUE"""),"Vespertino") | D4: Veio | E4: INFANTIL | F4: FEMININO | I4: =IFERROR(__xludf.DUMMYFUNCTION("FILTER($A:$A,$E:$E = ""MIRIM"", $F:$F = ""MASCULINO"", $D:$D = ""Veio"")"),"CAUÃ SOUZA PROCÓPIO DA SILVA") | J4: =IFERROR(__xludf.DUMMYFUNCTION("FILTER($B:$B,$E:$E = ""MIRIM"", $F:$F = ""MASCULINO"", $D:$D = ""Veio"")"),"Turma A") | K4: 3 | L4: Até 32Kg | M4: Até 22Kg | P4: =IFERROR(__xludf.DUMMYFUNCTION("FILTER($A:$A,$E:$E = ""MIRIM"", $F:$F = ""FEMININO"", $D:$D = ""Veio"")"),"AGATA LORRAINE ARAÚJO DA COSTA") | Q4: =IFERROR(__xludf.DUMMYFUNCTION("FILTER($B:$B,$E:$E = ""MIRIM"", $F:$F = ""FEMININO"", $D:$D = ""Veio"")"),"Turma A") | R4: 3 | S4: Até 28Kg | T4: Até 22Kg | W4: =IFERROR(__xludf.DUMMYFUNCTION("FILTER($A:$A,$E:$E = ""INFANTIL"", $F:$F = ""MASCULINO"", $D:$D = ""Veio"")"),"AQUIRIZ ARAUJO DE FREITAS") | X4: =IFERROR(__xludf.DUMMYFUNCTION("FILTER($B:$B,$E:$E = ""INFANTIL"", $F:$F = ""MASCULINO"", $D:$D = ""Veio"")"),"Turma C") | Y4: 3 | Z4: Acima de 45Kg | AA4: Até 30Kg | AD4: =IFERROR(__xludf.DUMMYFUNCTION("FILTER($A:$A,$E:$E = ""INFANTIL"", $F:$F = ""FEMININO"", $D:$D = ""Veio"")"),"ALLANA FERREIRA DA SILVA") | AE4: =IFERROR(__xludf.DUMMYFUNCTION("FILTER($B:$B,$E:$E = ""INFANTIL"", $F:$F = ""FEMININO"", $D:$D = ""Veio"")"),"Turma B1") | AG4: Até 35Kg | AH4: Até 30Kg | AK4: =IFERROR(__xludf.DUMMYFUNCTION("FILTER($A:$A,$E:$E = ""CADETE"", $F:$F = ""MASCULINO"", $D:$D = ""Veio"")"),"ALLAN ALVES RIBEIRO") | AL4: =IFERROR(__xludf.DUMMYFUNCTION("FILTER($B:$B,$E:$E = ""CADETE"", $F:$F = ""MASCULINO"", $D:$D = ""Veio"")"),"Turma E") | AN4: Até 53Kg | AO4: Até 37Kg | AR4: =IFERROR(__xludf.DUMMYFUNCTION("FILTER($A:$A,$E:$E = ""CADETE"", $F:$F = ""FEMININO"", $D:$D = ""Veio"")"),"Danielly Hilary Almeida Martins") | AS4: =IFERROR(__xludf.DUMMYFUNCTION("FILTER($B:$B,$E:$E = ""CADETE"", $F:$F = ""FEMININO"", $D:$D = ""Veio"")"),"Turma D") | AT4: 3 | AU4: Acima de 59Kg | AV4: Até 37Kg
A5: =IFERROR(__xludf.DUMMYFUNCTION("""COMPUTED_VALUE"""),"Allana Gonçalves Da Silva") | B5: =IFERROR(__xludf.DUMMYFUNCTION("""COMPUTED_VALUE"""),"Turma C") | C5: =IFERROR(__xludf.DUMMYFUNCTION("""COMPUTED_VALUE"""),"Matutino") | D5: Veio | E5: MIRIM | F5: FEMININO | I5: =IFERROR(__xludf.DUMMYFUNCTION("""COMPUTED_VALUE"""),"DANIEL VIEIRA MARTINS") | J5: =IFERROR(__xludf.DUMMYFUNCTION("""COMPUTED_VALUE"""),"Turma B1") | K5: 3 | L5: Até 28Kg | M5: Até 24Kg | P5: =IFERROR(__xludf.DUMMYFUNCTION("""COMPUTED_VALUE"""),"Allana Gonçalves Da Silva") | Q5: =IFERROR(__xludf.DUMMYFUNCTION("""COMPUTED_VALUE"""),"Turma C") | S5: Até 32Kg | T5: Até 24Kg | W5: =IFERROR(__xludf.DUMMYFUNCTION("""COMPUTED_VALUE"""),"Breno Henrique Germano Dos Santos") | X5: =IFERROR(__xludf.DUMMYFUNCTION("""COMPUTED_VALUE"""),"Turma C") | AA5: Até 35Kg | AD5: =IFERROR(__xludf.DUMMYFUNCTION("""COMPUTED_VALUE"""),"CLAUDIA GABRIELY CAMARGO MOREIRA") | AE5: =IFERROR(__xludf.DUMMYFUNCTION("""COMPUTED_VALUE"""),"Turma D") | AF5: 3 | AG5: Até 35Kg | AH5: Até 35Kg | AK5: =IFERROR(__xludf.DUMMYFUNCTION("""COMPUTED_VALUE"""),"DIEGO RENAN OLIVEIRA DA SILVA") | AL5: =IFERROR(__xludf.DUMMYFUNCTION("""COMPUTED_VALUE"""),"Turma E") | AM5: 3 | AN5: Até 61Kg | AO5: Até 45Kg | AR5: =IFERROR(__xludf.DUMMYFUNCTION("""COMPUTED_VALUE"""),"KAUANE BARBOSA LEMES") | AS5: =IFERROR(__xludf.DUMMYFUNCTION("""COMPUTED_VALUE"""),"Turma E") | AT5: 3 | AU5: Até 51Kg | AV5: Até 44Kg
A6: =IFERROR(__xludf.DUMMYFUNCTION("""COMPUTED_VALUE"""),"Ana Julia Da Cruz Oliveira") | B6: =IFERROR(__xludf.DUMMYFUNCTION("""COMPUTED_VALUE"""),"Turma A") | C6: =IFERROR(__xludf.DUMMYFUNCTION("""COMPUTED_VALUE"""),"Matutino") | D6: Veio | E6: MIRIM | F6: FEMININO | I6: =IFERROR(__xludf.DUMMYFUNCTION("""COMPUTED_VALUE"""),"DAVY THAYLOM OLIVEIRA DOS SANTOS") | J6: =IFERROR(__xludf.DUMMYFUNCTION("""COMPUTED_VALUE"""),"Turma A") | L6: Até 24Kg | M6: Até 26Kg | P6: =IFERROR(__xludf.DUMMYFUNCTION("""COMPUTED_VALUE"""),"Ana Julia Da Cruz Oliveira") | Q6: =IFERROR(__xludf.DUMMYFUNCTION("""COMPUTED_VALUE"""),"Turma A") | R6: 3 | S6: Até 26Kg | T6: Até 26Kg | W6: =IFERROR(__xludf.DUMMYFUNCTION("""COMPUTED_VALUE"""),"CARLOS DANIEL BARROSO FERREIRA") | X6: =IFERROR(__xludf.DUMMYFUNCTION("""COMPUTED_VALUE"""),"Turma C") | Z6: Até 40Kg | AA6: Até 40Kg | AD6: =IFERROR(__xludf.DUMMYFUNCTION("""COMPUTED_VALUE"""),"EMILLY VICTÓRIA DO NASCIMENTO BEZERRA") | AE6: =IFERROR(__xludf.DUMMYFUNCTION("""COMPUTED_VALUE"""),"Turma B2") | AG6: Até 45Kg | AH6: Até 40Kg | AK6: =IFERROR(__xludf.DUMMYFUNCTION("""COMPUTED_VALUE"""),"GUSTAVO GALVÃO DE JESUS") | AL6: =IFERROR(__xludf.DUMMYFUNCTION("""COMPUTED_VALUE"""),"Turma D") | AM6: 3 | AN6: Acima de 61Kg | AO6: Até 53Kg | AR6: =IFERROR(__xludf.DUMMYFUNCTION("""COMPUTED_VALUE"""),"KETLEN LORRANE DO NASCIMENTO DA SILVA") | AS6: =IFERROR(__xludf.DUMMYFUNCTION("""COMPUTED_VALUE"""),"Turma E") | AU6: Até 51Kg | AV6: Até 51Kg
A7: =IFERROR(__xludf.DUMMYFUNCTION("""COMPUTED_VALUE"""),"AQUIRIZ ARAUJO DE FREITAS") | B7: =IFERROR(__xludf.DUMMYFUNCTION("""COMPUTED_VALUE"""),"Turma C") | C7: =IFERROR(__xludf.DUMMYFUNCTION("""COMPUTED_VALUE"""),"Vespertino") | D7: Veio | E7: INFANTIL | F7: MASCULINO | I7: =IFERROR(__xludf.DUMMYFUNCTION("""COMPUTED_VALUE"""),"ERIK KAUAN DE SOUSA SILVA") | J7: =IFERROR(__xludf.DUMMYFUNCTION("""COMPUTED_VALUE"""),"Turma B1") | L7: Acima de 38Kg | M7: Até 28Kg | P7: =IFERROR(__xludf.DUMMYFUNCTION("""COMPUTED_VALUE"""),"Estela Martins Lopes") | Q7: =IFERROR(__xludf.DUMMYFUNCTION("""COMPUTED_VALUE"""),"Turma A") | S7: Até 36Kg | T7: Até 28Kg | W7: =IFERROR(__xludf.DUMMYFUNCTION("""COMPUTED_VALUE"""),"Carlos Eduardo De Souza") | X7: =IFERROR(__xludf.DUMMYFUNCTION("""COMPUTED_VALUE"""),"Turma D") | Z7: Até 40Kg | AA7: Até 45Kg | AD7: =IFERROR(__xludf.DUMMYFUNCTION("""COMPUTED_VALUE"""),"IARA YASMIN FERREIRA IZEL") | AE7: =IFERROR(__xludf.DUMMYFUNCTION("""COMPUTED_VALUE"""),"Turma B1") | AG7: Até 45Kg | AH7: Até 45Kg | AK7: =IFERROR(__xludf.DUMMYFUNCTION("""COMPUTED_VALUE"""),"JOÃO PEDRO JESUS SOUZA") | AL7: =IFERROR(__xludf.DUMMYFUNCTION("""COMPUTED_VALUE"""),"Turma E") | AN7: Até 61Kg | AO7: Até 61Kg | AR7: =IFERROR(__xludf.DUMMYFUNCTION("""COMPUTED_VALUE"""),"Lorena De Paiva Leite") | AS7: =IFERROR(__xludf.DUMMYFUNCTION("""COMPUTED_VALUE"""),"Turma D") | AU7: Até 51Kg | AV7: Até 59Kg
A8: =IFERROR(__xludf.DUMMYFUNCTION("""COMPUTED_VALUE"""),"Breno Henrique Germano Dos Santos") | B8: =IFERROR(__xludf.DUMMYFUNCTION("""COMPUTED_VALUE"""),"Turma C") | C8: =IFERROR(__xludf.DUMMYFUNCTION("""COMPUTED_VALUE"""),"Matutino") | D8: Veio | E8: INFANTIL | F8: MASCULINO | I8: =IFERROR(__xludf.DUMMYFUNCTION("""COMPUTED_VALUE"""),"LUIZ FELIPE POLICARPO DOS SANTOS") | J8: =IFERROR(__xludf.DUMMYFUNCTION("""COMPUTED_VALUE"""),"Turma A") | L8: Até 32Kg | M8: Até 30Kg | P8: =IFERROR(__xludf.DUMMYFUNCTION("""COMPUTED_VALUE"""),"HELLOARA SANTOS DE LIMA") | Q8: =IFERROR(__xludf.DUMMYFUNCTION("""COMPUTED_VALUE"""),"Turma B2") | R8: 3 | S8: Acima de 38Kg | T8: Até 30Kg | W8: =IFERROR(__xludf.DUMMYFUNCTION("""COMPUTED_VALUE"""),"CARLOS EDUARDO GENUINO DE ALENCAR") | X8: =IFERROR(__xludf.DUMMYFUNCTION("""COMPUTED_VALUE"""),"Turma C") | Z8: Acima de 45Kg | AA8: Acima de 45Kg | AD8: =IFERROR(__xludf.DUMMYFUNCTION("""COMPUTED_VALUE"""),"Kamily Barbosa Lemes") | AE8: =IFERROR(__xludf.DUMMYFUNCTION("""COMPUTED_VALUE"""),"Turma C") | AG8: Até 45Kg | AH8: Acima de 45Kg | AK8: =IFERROR(__xludf.DUMMYFUNCTION("""COMPUTED_VALUE"""),"Nicolas Araújo De Souza") | AL8: =IFERROR(__xludf.DUMMYFUNCTION("""COMPUTED_VALUE"""),"Turma D") | AN8: Acima de 61Kg | AO8: Acima de 61Kg | AR8: =IFERROR(__xludf.DUMMYFUNCTION("""COMPUTED_VALUE"""),"Mariah Sophia Sales Aniceto") | AS8: =IFERROR(__xludf.DUMMYFUNCTION("""COMPUTED_VALUE"""),"Turma D") | AU8: Até 51Kg | AV8: Acima de 59Kg
A9: =IFERROR(__xludf.DUMMYFUNCTION("""COMPUTED_VALUE"""),"CARLOS DANIEL BARROSO FERREIRA") | B9: =IFERROR(__xludf.DUMMYFUNCTION("""COMPUTED_VALUE"""),"Turma C") | C9: =IFERROR(__xludf.DUMMYFUNCTION("""COMPUTED_VALUE"""),"Vespertino") | D9: Veio | E9: INFANTIL | F9: MASCULINO | I9: =IFERROR(__xludf.DUMMYFUNCTION("""COMPUTED_VALUE"""),"MARCOS ANTÔNIO TRINDADE DA SILVA") | J9: =IFERROR(__xludf.DUMMYFUNCTION("""COMPUTED_VALUE"""),"Turma B1") | K9: 3 | L9: Até 34Kg | M9: Até 32Kg | P9: =IFERROR(__xludf.DUMMYFUNCTION("""COMPUTED_VALUE"""),"JHENIFFER YASMIN MENDES MORAES") | Q9: =IFERROR(__xludf.DUMMYFUNCTION("""COMPUTED_VALUE"""),"Turma A") | R9: 3 | S9: Até 32Kg | T9: Até 32Kg | W9: =IFERROR(__xludf.DUMMYFUNCTION("""COMPUTED_VALUE"""),"Darlan Guilherme Sobreiro Romero Da Silva") | X9: =IFERROR(__xludf.DUMMYFUNCTION("""COMPUTED_VALUE"""),"Turma D") | Y9: 3 | Z9: Até 40Kg | AK9: =IFERROR(__xludf.DUMMYFUNCTION("""COMPUTED_VALUE"""),"SAMUEL JUNIOR VERDAN FRANCISCO") | AL9: =IFERROR(__xludf.DUMMYFUNCTION("""COMPUTED_VALUE"""),"Turma D") | AM9: 3 | AN9: Acima de 61Kg | AR9: =IFERROR(__xludf.DUMMYFUNCTION("""COMPUTED_VALUE"""),"Valdenira Silva Do Nascimento") | AS9: =IFERROR(__xludf.DUMMYFUNCTION("""COMPUTED_VALUE"""),"Turma D") | AT9: 3 | AU9: Até 44Kg
A10: =IFERROR(__xludf.DUMMYFUNCTION("""COMPUTED_VALUE"""),"Carlos Eduardo De Souza") | B10: =IFERROR(__xludf.DUMMYFUNCTION("""COMPUTED_VALUE"""),"Turma D") | C10: =IFERROR(__xludf.DUMMYFUNCTION("""COMPUTED_VALUE"""),"Vespertino") | D10: Veio | E10: INFANTIL | F10: MASCULINO | I10: =IFERROR(__xludf.DUMMYFUNCTION("""COMPUTED_VALUE"""),"MIGUEL AUGUSTO DE LIMA TRINDADE") | J10: =IFERROR(__xludf.DUMMYFUNCTION("""COMPUTED_VALUE"""),"Turma B1") | K10: 3 | L10: Até 28Kg | M10: Até 34Kg | P10: =IFERROR(__xludf.DUMMYFUNCTION("""COMPUTED_VALUE"""),"Julia Emanuelly Lavratti Oliveira") | Q10: =IFERROR(__xludf.DUMMYFUNCTION("""COMPUTED_VALUE"""),"Turma A") | S10: Até 28Kg | T10: Até 34Kg | W10: =IFERROR(__xludf.DUMMYFUNCTION("""COMPUTED_VALUE"""),"DAVI LORENZO BARBOSA MOREIRA") | X10: =IFERROR(__xludf.DUMMYFUNCTION("""COMPUTED_VALUE"""),"Turma C") | Z10: Até 35Kg | AK10: =IFERROR(__xludf.DUMMYFUNCTION("""COMPUTED_VALUE"""),"WEVERTON LEONARDO VIEIRA MARTINS") | AL10: =IFERROR(__xludf.DUMMYFUNCTION("""COMPUTED_VALUE"""),"Turma D") | AN10: Até 53Kg | AR10: =IFERROR(__xludf.DUMMYFUNCTION("""COMPUTED_VALUE"""),"YASMYN THAUANY ALCANTARA MONTEIRO") | AS10: =IFERROR(__xludf.DUMMYFUNCTION("""COMPUTED_VALUE"""),"Turma D") | AU10: Até 44Kg
A11: =IFERROR(__xludf.DUMMYFUNCTION("""COMPUTED_VALUE"""),"CARLOS EDUARDO GENUINO DE ALENCAR") | B11: =IFERROR(__xludf.DUMMYFUNCTION("""COMPUTED_VALUE"""),"Turma C") | C11: =IFERROR(__xludf.DUMMYFUNCTION("""COMPUTED_VALUE"""),"Vespertino") | D11: Veio | E11: INFANTIL | F11: MASCULINO | I11: =IFERROR(__xludf.DUMMYFUNCTION("""COMPUTED_VALUE"""),"MIGUEL NYKOLAS DUTRA ALMEIDA") | J11: =IFERROR(__xludf.DUMMYFUNCTION("""COMPUTED_VALUE"""),"Turma B1") | L11: Até 30Kg | M11: Até 36Kg | P11: =IFERROR(__xludf.DUMMYFUNCTION("""COMPUTED_VALUE"""),"Kamilly Alves De Souza") | Q11: =IFERROR(__xludf.DUMMYFUNCTION("""COMPUTED_VALUE"""),"Turma A") | R11: 3 | S11: Até 24Kg | T11: Até 36Kg | W11: =IFERROR(__xludf.DUMMYFUNCTION("""COMPUTED_VALUE"""),"ENZO GABRIEL FERREIRA DOS SANTOS") | X11: =IFERROR(__xludf.DUMMYFUNCTION("""COMPUTED_VALUE"""),"Turma B2") | Z11: Até 35Kg | AN11: Até 53Kg
A12: =IFERROR(__xludf.DUMMYFUNCTION("""COMPUTED_VALUE"""),"CAUÃ SOUZA PROCÓPIO DA SILVA") | B12: =IFERROR(__xludf.DUMMYFUNCTION("""COMPUTED_VALUE"""),"Turma A") | C12: =IFERROR(__xludf.DUMMYFUNCTION("""COMPUTED_VALUE"""),"Vespertino") | D12: Veio | E12: MIRIM | F12: MASCULINO | I12: =IFERROR(__xludf.DUMMYFUNCTION("""COMPUTED_VALUE"""),"PEDRO HENRIQUE VIANA VELOSO") | J12: =IFERROR(__xludf.DUMMYFUNCTION("""COMPUTED_VALUE"""),"Turma B1") | L12: Até 28Kg | M12: Até 38Kg | P12: =IFERROR(__xludf.DUMMYFUNCTION("""COMPUTED_VALUE"""),"LUANA SOUSA RIVA") | Q12: =IFERROR(__xludf.DUMMYFUNCTION("""COMPUTED_VALUE"""),"Turma B1") | R12: 3 | S12: Até 36Kg | T12: Até 38Kg | W12: =IFERROR(__xludf.DUMMYFUNCTION("""COMPUTED_VALUE"""),"GABRIEL MARTINS DOS SANTOS") | X12: =IFERROR(__xludf.DUMMYFUNCTION("""COMPUTED_VALUE"""),"Turma C") | Z12: Até 40Kg
A13: =IFERROR(__xludf.DUMMYFUNCTION("""COMPUTED_VALUE"""),"CLAUDIA GABRIELY CAMARGO MOREIRA") | B13: =IFERROR(__xludf.DUMMYFUNCTION("""COMPUTED_VALUE"""),"Turma D") | C13: =IFERROR(__xludf.DUMMYFUNCTION("""COMPUTED_VALUE"""),"Matutino") | D13: Veio | E13: INFANTIL | F13: FEMININO | I13: =IFERROR(__xludf.DUMMYFUNCTION("""COMPUTED_VALUE"""),"PIETRO HENRIQUE OLIVEIRA JACOMINO") | J13: =IFERROR(__xludf.DUMMYFUNCTION("""COMPUTED_VALUE"""),"Turma A") | K13: 3 | L13: Até 28Kg | M13: Acima de 38Kg | P13: =IFERROR(__xludf.DUMMYFUNCTION("""COMPUTED_VALUE"""),"MARIA EDUARDA SOBREIRO DA SILVA") | Q13: =IFERROR(__xludf.DUMMYFUNCTION("""COMPUTED_VALUE"""),"Turma B1") | S13: Até 32Kg | T13: Acima de 38Kg | W13: =IFERROR(__xludf.DUMMYFUNCTION("""COMPUTED_VALUE"""),"Henrique Rocha Almeida") | X13: =IFERROR(__xludf.DUMMYFUNCTION("""COMPUTED_VALUE"""),"Turma D") | Z13: Acima de 45Kg
A14: =IFERROR(__xludf.DUMMYFUNCTION("""COMPUTED_VALUE"""),"DANIEL VIEIRA MARTINS") | B14: =IFERROR(__xludf.DUMMYFUNCTION("""COMPUTED_VALUE"""),"Turma B1") | C14: =IFERROR(__xludf.DUMMYFUNCTION("""COMPUTED_VALUE"""),"Matutino") | D14: Veio | E14: MIRIM | F14: MASCULINO | I14: =IFERROR(__xludf.DUMMYFUNCTION("""COMPUTED_VALUE"""),"RAFAEL MENDES DA SILVA") | J14: =IFERROR(__xludf.DUMMYFUNCTION("""COMPUTED_VALUE"""),"Turma B1") | L14: Até 24Kg | P14: =IFERROR(__xludf.DUMMYFUNCTION("""COMPUTED_VALUE"""),"MARIA FERNANDA DOS SANTOS KUBOTA") | Q14: =IFERROR(__xludf.DUMMYFUNCTION("""COMPUTED_VALUE"""),"Turma B2") | S14: Até 26Kg | W14: =IFERROR(__xludf.DUMMYFUNCTION("""COMPUTED_VALUE"""),"Luis Felipe Camargo Moreira") | X14: =IFERROR(__xludf.DUMMYFUNCTION("""COMPUTED_VALUE"""),"Turma D") | Z14: Até 45Kg
A15: =IFERROR(__xludf.DUMMYFUNCTION("""COMPUTED_VALUE"""),"Danielly Hilary Almeida Martins") | B15: =IFERROR(__xludf.DUMMYFUNCTION("""COMPUTED_VALUE"""),"Turma D") | C15: =IFERROR(__xludf.DUMMYFUNCTION("""COMPUTED_VALUE"""),"Vespertino") | D15: Veio | E15: CADETE | F15: FEMININO | I15: =IFERROR(__xludf.DUMMYFUNCTION("""COMPUTED_VALUE"""),"VICTOR EMANUEL ALMEIDA MARTINS") | J15: =IFERROR(__xludf.DUMMYFUNCTION("""COMPUTED_VALUE"""),"Turma B1") | K15: 3 | P15: =IFERROR(__xludf.DUMMYFUNCTION("""COMPUTED_VALUE"""),"NICOLLY DE PAULO DUTRA") | Q15: =IFERROR(__xludf.DUMMYFUNCTION("""COMPUTED_VALUE"""),"Turma B1") | S15: Até 36Kg | W15: =IFERROR(__xludf.DUMMYFUNCTION("""COMPUTED_VALUE"""),"PIETRO FRANCISCO GALVÃO DE JESUS") | X15: =IFERROR(__xludf.DUMMYFUNCTION("""COMPUTED_VALUE"""),"Turma D") | Z15: Até 40Kg
A16: =IFERROR(__xludf.DUMMYFUNCTION("""COMPUTED_VALUE"""),"Darlan Guilherme Sobreiro Romero Da Silva") | B16: =IFERROR(__xludf.DUMMYFUNCTION("""COMPUTED_VALUE"""),"Turma D") | C16: =IFERROR(__xludf.DUMMYFUNCTION("""COMPUTED_VALUE"""),"Vespertino") | D16: Veio | E16: INFANTIL | F16: MASCULINO | L16: Acima de 38Kg | P16: =IFERROR(__xludf.DUMMYFUNCTION("""COMPUTED_VALUE"""),"Raquel Vieira Martins") | Q16: =IFERROR(__xludf.DUMMYFUNCTION("""COMPUTED_VALUE"""),"Turma A") | S16: Até 32Kg | W16: =IFERROR(__xludf.DUMMYFUNCTION("""COMPUTED_VALUE"""),"Ruan Brayan Alcantara Monteiro") | X16: =IFERROR(__xludf.DUMMYFUNCTION("""COMPUTED_VALUE"""),"Turma D") | Z16: Até 45Kg
A17: =IFERROR(__xludf.DUMMYFUNCTION("""COMPUTED_VALUE"""),"DAVI LORENZO BARBOSA MOREIRA") | B17: =IFERROR(__xludf.DUMMYFUNCTION("""COMPUTED_VALUE"""),"Turma C") | C17: =IFERROR(__xludf.DUMMYFUNCTION("""COMPUTED_VALUE"""),"Vespertino") | D17: Veio | E17: INFANTIL | F17: MASCULINO | W17: =IFERROR(__xludf.DUMMYFUNCTION("""COMPUTED_VALUE"""),"Thalles Ramon Da Pascoa Silva") | X17: =IFERROR(__xludf.DUMMYFUNCTION("""COMPUTED_VALUE"""),"Turma D") | Z17: Até 35Kg
A18: =IFERROR(__xludf.DUMMYFUNCTION("""COMPUTED_VALUE"""),"DAVY THAYLOM OLIVEIRA DOS SANTOS") | B18: =IFERROR(__xludf.DUMMYFUNCTION("""COMPUTED_VALUE"""),"Turma A") | C18: =IFERROR(__xludf.DUMMYFUNCTION("""COMPUTED_VALUE"""),"Vespertino") | D18: Veio | E18: MIRIM | F18: MASCULINO | W18: =IFERROR(__xludf.DUMMYFUNCTION("""COMPUTED_VALUE"""),"THIAGO PAULINO PEREIRA DE ARAÚJO") | X18: =IFERROR(__xludf.DUMMYFUNCTION("""COMPUTED_VALUE"""),"Turma B1") | Z18: Até 35Kg
A19: =IFERROR(__xludf.DUMMYFUNCTION("""COMPUTED_VALUE"""),"DIEGO RENAN OLIVEIRA DA SILVA") | B19: =IFERROR(__xludf.DUMMYFUNCTION("""COMPUTED_VALUE"""),"Turma E") | C19: =IFERROR(__xludf.DUMMYFUNCTION("""COMPUTED_VALUE"""),"Vespertino") | D19: Veio | E19: CADETE | F19: MASCULINO
A20: =IFERROR(__xludf.DUMMYFUNCTION("""COMPUTED_VALUE"""),"EMILLY VICTÓRIA DO NASCIMENTO BEZERRA") | B20: =IFERROR(__xludf.DUMMYFUNCTION("""COMPUTED_VALUE"""),"Turma B2") | C20: =IFERROR(__xludf.DUMMYFUNCTION("""COMPUTED_VALUE"""),"Vespertino") | D20: Veio | E20: INFANTIL | F20: FEMININO
A21: =IFERROR(__xludf.DUMMYFUNCTION("""COMPUTED_VALUE"""),"ENZO GABRIEL FERREIRA DOS SANTOS") | B21: =IFERROR(__xludf.DUMMYFUNCTION("""COMPUTED_VALUE"""),"Turma B2") | C21: =IFERROR(__xludf.DUMMYFUNCTION("""COMPUTED_VALUE"""),"Vespertino") | D21: Veio | E21: INFANTIL | F21: MASCULINO
A22: =IFERROR(__xludf.DUMMYFUNCTION("""COMPUTED_VALUE"""),"ERIK KAUAN DE SOUSA SILVA") | B22: =IFERROR(__xludf.DUMMYFUNCTION("""COMPUTED_VALUE"""),"Turma B1") | C22: =IFERROR(__xludf.DUMMYFUNCTION("""COMPUTED_VALUE"""),"Matutino") | D22: Veio | E22: MIRIM | F22: MASCULINO
A23: =IFERROR(__xludf.DUMMYFUNCTION("""COMPUTED_VALUE"""),"Estela Martins Lopes") | B23: =IFERROR(__xludf.DUMMYFUNCTION("""COMPUTED_VALUE"""),"Turma A") | C23: =IFERROR(__xludf.DUMMYFUNCTION("""COMPUTED_VALUE"""),"Matutino") | D23: Veio | E23: MIRIM | F23: FEMININO
A24: =IFERROR(__xludf.DUMMYFUNCTION("""COMPUTED_VALUE"""),"GABRIEL MARTINS DOS SANTOS") | B24: =IFERROR(__xludf.DUMMYFUNCTION("""COMPUTED_VALUE"""),"Turma C") | C24: =IFERROR(__xludf.DUMMYFUNCTION("""COMPUTED_VALUE"""),"Vespertino") | D24: Veio | E24: INFANTIL | F24: MASCULINO
A25: =IFERROR(__xludf.DUMMYFUNCTION("""COMPUTED_VALUE"""),"GUSTAVO GALVÃO DE JESUS") | B25: =IFERROR(__xludf.DUMMYFUNCTION("""COMPUTED_VALUE"""),"Turma D") | C25: =IFERROR(__xludf.DUMMYFUNCTION("""COMPUTED_VALUE"""),"Matutino") | D25: Veio | E25: CADETE | F25: MASCULINO
A26: =IFERROR(__xludf.DUMMYFUNCTION("""COMPUTED_VALUE"""),"HELLOARA SANTOS DE LIMA") | B26: =IFERROR(__xludf.DUMMYFUNCTION("""COMPUTED_VALUE"""),"Turma B2") | C26: =IFERROR(__xludf.DUMMYFUNCTION("""COMPUTED_VALUE"""),"Matutino") | D26: Veio | E26: MIRIM | F26: FEMININO
A27: =IFERROR(__xludf.DUMMYFUNCTION("""COMPUTED_VALUE"""),"Henrique Rocha Almeida") | B27: =IFERROR(__xludf.DUMMYFUNCTION("""COMPUTED_VALUE"""),"Turma D") | C27: =IFERROR(__xludf.DUMMYFUNCTION("""COMPUTED_VALUE"""),"Vespertino") | D27: Veio | E27: INFANTIL | F27: MASCULINO
A28: =IFERROR(__xludf.DUMMYFUNCTION("""COMPUTED_VALUE"""),"IARA YASMIN FERREIRA IZEL") | B28: =IFERROR(__xludf.DUMMYFUNCTION("""COMPUTED_VALUE"""),"Turma B1") | C28: =IFERROR(__xludf.DUMMYFUNCTION("""COMPUTED_VALUE"""),"Vespertino") | D28: Veio | E28: INFANTIL | F28: FEMININO
A29: =IFERROR(__xludf.DUMMYFUNCTION("""COMPUTED_VALUE"""),"JHENIFFER YASMIN MENDES MORAES") | B29: =IFERROR(__xludf.DUMMYFUNCTION("""COMPUTED_VALUE"""),"Turma A") | C29: =IFERROR(__xludf.DUMMYFUNCTION("""COMPUTED_VALUE"""),"Vespertino") | D29: Veio | E29: MIRIM | F29: FEMININO
A30: =IFERROR(__xludf.DUMMYFUNCTION("""COMPUTED_VALUE"""),"JOÃO PEDRO JESUS SOUZA") | B30: =IFERROR(__xludf.DUMMYFUNCTION("""COMPUTED_VALUE"""),"Turma E") | C30: =IFERROR(__xludf.DUMMYFUNCTION("""COMPUTED_VALUE"""),"Vespertino") | D30: Veio | E30: CADETE | F30: MASCULINO
A31: =IFERROR(__xludf.DUMMYFUNCTION("""COMPUTED_VALUE"""),"Julia Emanuelly Lavratti Oliveira") | B31: =IFERROR(__xludf.DUMMYFUNCTION("""COMPUTED_VALUE"""),"Turma A") | C31: =IFERROR(__xludf.DUMMYFUNCTION("""COMPUTED_VALUE"""),"Matutino") | D31: Veio | E31: MIRIM | F31: FEMININO
A32: =IFERROR(__xludf.DUMMYFUNCTION("""COMPUTED_VALUE"""),"Kamilly Alves De Souza") | B32: =IFERROR(__xludf.DUMMYFUNCTION("""COMPUTED_VALUE"""),"Turma A") | C32: =IFERROR(__xludf.DUMMYFUNCTION("""COMPUTED_VALUE"""),"Matutino") | D32: Veio | E32: MIRIM | F32: FEMININO
A33: =IFERROR(__xludf.DUMMYFUNCTION("""COMPUTED_VALUE"""),"Kamily Barbosa Lemes") | B33: =IFERROR(__xludf.DUMMYFUNCTION("""COMPUTED_VALUE"""),"Turma C") | C33: =IFERROR(__xludf.DUMMYFUNCTION("""COMPUTED_VALUE"""),"Matutino") | D33: Veio | E33: INFANTIL | F33: FEMININO
A34: =IFERROR(__xludf.DUMMYFUNCTION("""COMPUTED_VALUE"""),"KAUANE BARBOSA LEMES") | B34: =IFERROR(__xludf.DUMMYFUNCTION("""COMPUTED_VALUE"""),"Turma E") | C34: =IFERROR(__xludf.DUMMYFUNCTION("""COMPUTED_VALUE"""),"Vespertino") | D34: Veio | E34: CADETE | F34: FEMININO
A35: =IFERROR(__xludf.DUMMYFUNCTION("""COMPUTED_VALUE"""),"KETLEN LORRANE DO NASCIMENTO DA SILVA") | B35: =IFERROR(__xludf.DUMMYFUNCTION("""COMPUTED_VALUE"""),"Turma E") | C35: =IFERROR(__xludf.DUMMYFUNCTION("""COMPUTED_VALUE"""),"Matutino") | D35: Veio | E35: CADETE | F35: FEMININO
A36: =IFERROR(__xludf.DUMMYFUNCTION("""COMPUTED_VALUE"""),"Lorena De Paiva Leite") | B36: =IFERROR(__xludf.DUMMYFUNCTION("""COMPUTED_VALUE"""),"Turma D") | C36: =IFERROR(__xludf.DUMMYFUNCTION("""COMPUTED_VALUE"""),"Vespertino") | D36: Veio | E36: CADETE | F36: FEMININO
A37: =IFERROR(__xludf.DUMMYFUNCTION("""COMPUTED_VALUE"""),"LUANA SOUSA RIVA") | B37: =IFERROR(__xludf.DUMMYFUNCTION("""COMPUTED_VALUE"""),"Turma B1") | C37: =IFERROR(__xludf.DUMMYFUNCTION("""COMPUTED_VALUE"""),"Matutino") | D37: Veio | E37: MIRIM | F37: FEMININO
A38: =IFERROR(__xludf.DUMMYFUNCTION("""COMPUTED_VALUE"""),"Luis Felipe Camargo Moreira") | B38: =IFERROR(__xludf.DUMMYFUNCTION("""COMPUTED_VALUE"""),"Turma D") | C38: =IFERROR(__xludf.DUMMYFUNCTION("""COMPUTED_VALUE"""),"Vespertino") | D38: Veio | E38: INFANTIL | F38: MASCULINO
A39: =IFERROR(__xludf.DUMMYFUNCTION("""COMPUTED_VALUE"""),"LUIZ FELIPE POLICARPO DOS SANTOS") | B39: =IFERROR(__xludf.DUMMYFUNCTION("""COMPUTED_VALUE"""),"Turma A") | C39: =IFERROR(__xludf.DUMMYFUNCTION("""COMPUTED_VALUE"""),"Vespertino") | D39: Veio | E39: MIRIM | F39: MASCULINO
A40: =IFERROR(__xludf.DUMMYFUNCTION("""COMPUTED_VALUE"""),"MARCOS ANTÔNIO TRINDADE DA SILVA") | B40: =IFERROR(__xludf.DUMMYFUNCTION("""COMPUTED_VALUE"""),"Turma B1") | C40: =IFERROR(__xludf.DUMMYFUNCTION("""COMPUTED_VALUE"""),"Vespertino") | D40: Veio | E40: MIRIM | F40: MASCULINO
...

Sheet Individual Ginastica
A1: Competidores | B1: Turma | C1: Período | D1: Presente | E1: Categoria | G1: PRÉ-INFANTIL | K1: INFANTIL | O1: JUVENIL | S1: ADULTO
A2: =IFERROR(__xludf.DUMMYFUNCTION("FILTER(Alunos!A:A, Alunos!$K:$K = ""Participa"")"),"AGATA LORRAINE ARAÚJO DA COSTA") | B2: =IFERROR(__xludf.DUMMYFUNCTION("FILTER(Alunos!B:B, Alunos!$K:$K = ""Participa"")"),"Turma A") | C2: =IFERROR(__xludf.DUMMYFUNCTION("FILTER(Alunos!C:C, Alunos!$K:$K = ""Participa"")"),"Vespertino") | D2: Veio | E2: ADULTO | G2: MÃOS LIVRES | K2: BOLA | O2: BOLA | S2: ARCO
A3: =IFERROR(__xludf.DUMMYFUNCTION("""COMPUTED_VALUE"""),"Ágatha Sophhie Da Silva Basílio") | B3: =IFERROR(__xludf.DUMMYFUNCTION("""COMPUTED_VALUE"""),"Turma A") | C3: =IFERROR(__xludf.DUMMYFUNCTION("""COMPUTED_VALUE"""),"Matutino") | D3: Veio | E3: INFANTIL | G3: COLOCAÇÃO | H3: ALUNA | I3: PONTOS | K3: COLOCAÇÃO | L3: ALUNA | M3: PONTOS | O3: COLOCAÇÃO | P3: ALUNA | Q3: PONTOS | S3: COLOCAÇÃO | T3: ALUNA | U3: PONTOS
A4: =IFERROR(__xludf.DUMMYFUNCTION("""COMPUTED_VALUE"""),"ALLANA FERREIRA DA SILVA") | B4: =IFERROR(__xludf.DUMMYFUNCTION("""COMPUTED_VALUE"""),"Turma B1") | C4: =IFERROR(__xludf.DUMMYFUNCTION("""COMPUTED_VALUE"""),"Vespertino") | D4: Veio | E4: JUVENIL | H4: =IFERROR(__xludf.DUMMYFUNCTION("FILTER($A:$A, $E:$E = ""PRÉ-INFANTIL"", $D:$D = ""Veio"")"),"ANA CLARA DE FREITAS TEIXEIRA") | L4: =IFERROR(__xludf.DUMMYFUNCTION("FILTER($A:$A, $E:$E = ""INFANTIL"", $D:$D = ""Veio"")"),"Ágatha Sophhie Da Silva Basílio") | P4: =IFERROR(__xludf.DUMMYFUNCTION("FILTER($A:$A, $E:$E = ""JUVENIL"", $D:$D = ""Veio"")"),"ALLANA FERREIRA DA SILVA") | T4: =IFERROR(__xludf.DUMMYFUNCTION("FILTER($A:$A, $E:$E = ""ADULTO"", $D:$D = ""Veio"")"),"AGATA LORRAINE ARAÚJO DA COSTA")
A5: =IFERROR(__xludf.DUMMYFUNCTION("""COMPUTED_VALUE"""),"ANA CLARA DE FREITAS TEIXEIRA") | B5: =IFERROR(__xludf.DUMMYFUNCTION("""COMPUTED_VALUE"""),"Turma GR") | C5: =IFERROR(__xludf.DUMMYFUNCTION("""COMPUTED_VALUE"""),"Vespertino") | D5: Veio | E5: PRÉ-INFANTIL | H5: =IFERROR(__xludf.DUMMYFUNCTION("""COMPUTED_VALUE"""),"Ana Vitória Santana Oliveira Da Silva") | L5: =IFERROR(__xludf.DUMMYFUNCTION("""COMPUTED_VALUE"""),"Ana Julia Da Cruz Oliveira") | P5: =IFERROR(__xludf.DUMMYFUNCTION("""COMPUTED_VALUE"""),"Daffiny De Jesus Silva") | T5: =IFERROR(__xludf.DUMMYFUNCTION("""COMPUTED_VALUE"""),"EMANUELY VITORIA BRITO DOS SANTOS")
A6: =IFERROR(__xludf.DUMMYFUNCTION("""COMPUTED_VALUE"""),"Ana Julia Da Cruz Oliveira") | B6: =IFERROR(__xludf.DUMMYFUNCTION("""COMPUTED_VALUE"""),"Turma A") | C6: =IFERROR(__xludf.DUMMYFUNCTION("""COMPUTED_VALUE"""),"Matutino") | D6: Veio | E6: INFANTIL | H6: =IFERROR(__xludf.DUMMYFUNCTION("""COMPUTED_VALUE"""),"ANNY HELOISE OLIVEIRA DA SILVA") | P6: =IFERROR(__xludf.DUMMYFUNCTION("""COMPUTED_VALUE"""),"SÂMILY PROCOPIO DA SILVA") | T6: =IFERROR(__xludf.DUMMYFUNCTION("""COMPUTED_VALUE"""),"EMILY VITÓRIA DA SILVA SANTOS")
A7: =IFERROR(__xludf.DUMMYFUNCTION("""COMPUTED_VALUE"""),"Ana Vitória Santana Oliveira Da Silva") | B7: =IFERROR(__xludf.DUMMYFUNCTION("""COMPUTED_VALUE"""),"Turma A") | C7: =IFERROR(__xludf.DUMMYFUNCTION("""COMPUTED_VALUE"""),"Matutino") | D7: Veio | E7: PRÉ-INFANTIL | H7: =IFERROR(__xludf.DUMMYFUNCTION("""COMPUTED_VALUE"""),"BEATRIZ COSTA ARAGÃO") | T7: =IFERROR(__xludf.DUMMYFUNCTION("""COMPUTED_VALUE"""),"Estela Martins Lopes")
A8: =IFERROR(__xludf.DUMMYFUNCTION("""COMPUTED_VALUE"""),"ANNY HELOISE OLIVEIRA DA SILVA") | B8: =IFERROR(__xludf.DUMMYFUNCTION("""COMPUTED_VALUE"""),"Turma B2") | C8: =IFERROR(__xludf.DUMMYFUNCTION("""COMPUTED_VALUE"""),"Vespertino") | D8: Veio | E8: PRÉ-INFANTIL | H8: =IFERROR(__xludf.DUMMYFUNCTION("""COMPUTED_VALUE"""),"EMANIELLY VITÓRIA PORTUGAL DE ALMEIDA") | T8: =IFERROR(__xludf.DUMMYFUNCTION("""COMPUTED_VALUE"""),"ESTHER PROCOPIO DA SILVA")
A9: =IFERROR(__xludf.DUMMYFUNCTION("""COMPUTED_VALUE"""),"BEATRIZ COSTA ARAGÃO") | B9: =IFERROR(__xludf.DUMMYFUNCTION("""COMPUTED_VALUE"""),"Turma GR") | C9: =IFERROR(__xludf.DUMMYFUNCTION("""COMPUTED_VALUE"""),"Vespertino") | D9: Veio | E9: PRÉ-INFANTIL | H9: =IFERROR(__xludf.DUMMYFUNCTION("""COMPUTED_VALUE"""),"VICTOR EMANUEL ALMEIDA MARTINS") | T9: =IFERROR(__xludf.DUMMYFUNCTION("""COMPUTED_VALUE"""),"HELOYSA FERNANDA ALVARENGA DOS SANTOS")
A10: =IFERROR(__xludf.DUMMYFUNCTION("""COMPUTED_VALUE"""),"Daffiny De Jesus Silva") | B10: =IFERROR(__xludf.DUMMYFUNCTION("""COMPUTED_VALUE"""),"Turma A") | C10: =IFERROR(__xludf.DUMMYFUNCTION("""COMPUTED_VALUE"""),"Matutino") | D10: Veio | E10: JUVENIL | T10: =IFERROR(__xludf.DUMMYFUNCTION("""COMPUTED_VALUE"""),"ISABELLA MIRANDA DA SILVA")
A11: =IFERROR(__xludf.DUMMYFUNCTION("""COMPUTED_VALUE"""),"EMANIELLY VITÓRIA PORTUGAL DE ALMEIDA") | B11: =IFERROR(__xludf.DUMMYFUNCTION("""COMPUTED_VALUE"""),"Turma C") | C11: =IFERROR(__xludf.DUMMYFUNCTION("""COMPUTED_VALUE"""),"Vespertino") | D11: Veio | E11: PRÉ-INFANTIL | T11: =IFERROR(__xludf.DUMMYFUNCTION("""COMPUTED_VALUE"""),"ISIS EDUARDA ALMEIDA MOITINHO")
A12: =IFERROR(__xludf.DUMMYFUNCTION("""COMPUTED_VALUE"""),"EMANUELY VITORIA BRITO DOS SANTOS") | B12: =IFERROR(__xludf.DUMMYFUNCTION("""COMPUTED_VALUE"""),"Turma A") | C12: =IFERROR(__xludf.DUMMYFUNCTION("""COMPUTED_VALUE"""),"Vespertino") | D12: Veio | E12: ADULTO | T12: =IFERROR(__xludf.DUMMYFUNCTION("""COMPUTED_VALUE"""),"JANAÍNA ARRUDA BONIN")
A13: =IFERROR(__xludf.DUMMYFUNCTION("""COMPUTED_VALUE"""),"EMILY VITÓRIA DA SILVA SANTOS") | B13: =IFERROR(__xludf.DUMMYFUNCTION("""COMPUTED_VALUE"""),"Turma GR") | C13: =IFERROR(__xludf.DUMMYFUNCTION("""COMPUTED_VALUE"""),"Vespertino") | D13: Veio | E13: ADULTO | T13: =IFERROR(__xludf.DUMMYFUNCTION("""COMPUTED_VALUE"""),"Julia Emanuelly Lavratti Oliveira")
A14: =IFERROR(__xludf.DUMMYFUNCTION("""COMPUTED_VALUE"""),"Estela Martins Lopes") | B14: =IFERROR(__xludf.DUMMYFUNCTION("""COMPUTED_VALUE"""),"Turma A") | C14: =IFERROR(__xludf.DUMMYFUNCTION("""COMPUTED_VALUE"""),"Matutino") | D14: Veio | E14: ADULTO | T14: =IFERROR(__xludf.DUMMYFUNCTION("""COMPUTED_VALUE"""),"Kamilly Alves De Souza")
A15: =IFERROR(__xludf.DUMMYFUNCTION("""COMPUTED_VALUE"""),"ESTHER PROCOPIO DA SILVA") | B15: =IFERROR(__xludf.DUMMYFUNCTION("""COMPUTED_VALUE"""),"Turma GR") | C15: =IFERROR(__xludf.DUMMYFUNCTION("""COMPUTED_VALUE"""),"Vespertino") | D15: Veio | E15: ADULTO | T15: =IFERROR(__xludf.DUMMYFUNCTION("""COMPUTED_VALUE"""),"LUANA DO NASCIMENTO FERNANDES")
A16: =IFERROR(__xludf.DUMMYFUNCTION("""COMPUTED_VALUE"""),"HELOYSA FERNANDA ALVARENGA DOS SANTOS") | B16: =IFERROR(__xludf.DUMMYFUNCTION("""COMPUTED_VALUE"""),"Turma B1") | C16: =IFERROR(__xludf.DUMMYFUNCTION("""COMPUTED_VALUE"""),"Vespertino") | D16: Veio | E16: ADULTO | T16: =IFERROR(__xludf.DUMMYFUNCTION("""COMPUTED_VALUE"""),"MARIA FERNANDA DOS SANTOS KUBOTA")
A17: =IFERROR(__xludf.DUMMYFUNCTION("""COMPUTED_VALUE"""),"ISABELLA MIRANDA DA SILVA") | B17: =IFERROR(__xludf.DUMMYFUNCTION("""COMPUTED_VALUE"""),"Turma B1") | C17: =IFERROR(__xludf.DUMMYFUNCTION("""COMPUTED_VALUE"""),"Vespertino") | D17: Veio | E17: ADULTO | T17: =IFERROR(__xludf.DUMMYFUNCTION("""COMPUTED_VALUE"""),"MARIA LUÍSA BARROS DA ROCHA")
A18: =IFERROR(__xludf.DUMMYFUNCTION("""COMPUTED_VALUE"""),"ISIS EDUARDA ALMEIDA MOITINHO") | B18: =IFERROR(__xludf.DUMMYFUNCTION("""COMPUTED_VALUE"""),"Turma A") | C18: =IFERROR(__xludf.DUMMYFUNCTION("""COMPUTED_VALUE"""),"Vespertino") | D18: Veio | E18: ADULTO | T18: =IFERROR(__xludf.DUMMYFUNCTION("""COMPUTED_VALUE"""),"Mikaela Tonete Santana")
A19: =IFERROR(__xludf.DUMMYFUNCTION("""COMPUTED_VALUE"""),"JANAÍNA ARRUDA BONIN") | B19: =IFERROR(__xludf.DUMMYFUNCTION("""COMPUTED_VALUE"""),"Turma B2") | C19: =IFERROR(__xludf.DUMMYFUNCTION("""COMPUTED_VALUE"""),"Matutino") | D19: Veio | E19: ADULTO | T19: =IFERROR(__xludf.DUMMYFUNCTION("""COMPUTED_VALUE"""),"NICOLLY DE PAULO DUTRA")
A20: =IFERROR(__xludf.DUMMYFUNCTION("""COMPUTED_VALUE"""),"Julia Emanuelly Lavratti Oliveira") | B20: =IFERROR(__xludf.DUMMYFUNCTION("""COMPUTED_VALUE"""),"Turma A") | C20: =IFERROR(__xludf.DUMMYFUNCTION("""COMPUTED_VALUE"""),"Matutino") | D20: Veio | E20: ADULTO | T20: =IFERROR(__xludf.DUMMYFUNCTION("""COMPUTED_VALUE"""),"NICOLY CAMARGO MOREIRA")
A21: =IFERROR(__xludf.DUMMYFUNCTION("""COMPUTED_VALUE"""),"Kamilly Alves De Souza") | B21: =IFERROR(__xludf.DUMMYFUNCTION("""COMPUTED_VALUE"""),"Turma A") | C21: =IFERROR(__xludf.DUMMYFUNCTION("""COMPUTED_VALUE"""),"Matutino") | D21: Veio | E21: ADULTO | T21: =IFERROR(__xludf.DUMMYFUNCTION("""COMPUTED_VALUE"""),"REBEKAH HOTTS DE SOUZA")
A22: =IFERROR(__xludf.DUMMYFUNCTION("""COMPUTED_VALUE"""),"LUANA DO NASCIMENTO FERNANDES") | B22: =IFERROR(__xludf.DUMMYFUNCTION("""COMPUTED_VALUE"""),"Turma B2") | C22: =IFERROR(__xludf.DUMMYFUNCTION("""COMPUTED_VALUE"""),"Vespertino") | D22: Veio | E22: ADULTO | T22: =IFERROR(__xludf.DUMMYFUNCTION("""COMPUTED_VALUE"""),"SOPHIA JATOBÁ DOS SANTOS")
A23: =IFERROR(__xludf.DUMMYFUNCTION("""COMPUTED_VALUE"""),"MARIA FERNANDA DOS SANTOS KUBOTA") | B23: =IFERROR(__xludf.DUMMYFUNCTION("""COMPUTED_VALUE"""),"Turma B2") | C23: =IFERROR(__xludf.DUMMYFUNCTION("""COMPUTED_VALUE"""),"Matutino") | D23: Veio | E23: ADULTO
A24: =IFERROR(__xludf.DUMMYFUNCTION("""COMPUTED_VALUE"""),"MARIA LUÍSA BARROS DA ROCHA") | B24: =IFERROR(__xludf.DUMMYFUNCTION("""COMPUTED_VALUE"""),"Turma C") | C24: =IFERROR(__xludf.DUMMYFUNCTION("""COMPUTED_VALUE"""),"Vespertino") | D24: Veio | E24: ADULTO
A25: =IFERROR(__xludf.DUMMYFUNCTION("""COMPUTED_VALUE"""),"Mikaela Tonete Santana") | B25: =IFERROR(__xludf.DUMMYFUNCTION("""COMPUTED_VALUE"""),"Turma C") | C25: =IFERROR(__xludf.DUMMYFUNCTION("""COMPUTED_VALUE"""),"Matutino") | D25: Veio | E25: ADULTO
A26: =IFERROR(__xludf.DUMMYFUNCTION("""COMPUTED_VALUE"""),"NICOLLY DE PAULO DUTRA") | B26: =IFERROR(__xludf.DUMMYFUNCTION("""COMPUTED_VALUE"""),"Turma B1") | C26: =IFERROR(__xludf.DUMMYFUNCTION("""COMPUTED_VALUE"""),"Vespertino") | D26: Veio | E26: ADULTO
A27: =IFERROR(__xludf.DUMMYFUNCTION("""COMPUTED_VALUE"""),"NICOLY CAMARGO MOREIRA") | B27: =IFERROR(__xludf.DUMMYFUNCTION("""COMPUTED_VALUE"""),"Turma B2") | C27: =IFERROR(__xludf.DUMMYFUNCTION("""COMPUTED_VALUE"""),"Matutino") | D27: Veio | E27: ADULTO
A28: =IFERROR(__xludf.DUMMYFUNCTION("""COMPUTED_VALUE"""),"REBEKAH HOTTS DE SOUZA") | B28: =IFERROR(__xludf.DUMMYFUNCTION("""COMPUTED_VALUE"""),"Turma GR") | C28: =IFERROR(__xludf.DUMMYFUNCTION("""COMPUTED_VALUE"""),"Vespertino") | D28: Veio | E28: ADULTO
A29: =IFERROR(__xludf.DUMMYFUNCTION("""COMPUTED_VALUE"""),"SÂMILY PROCOPIO DA SILVA") | B29: =IFERROR(__xludf.DUMMYFUNCTION("""COMPUTED_VALUE"""),"Turma GR") | C29: =IFERROR(__xludf.DUMMYFUNCTION("""COMPUTED_VALUE"""),"Vespertino") | D29: Veio | E29: JUVENIL
A30: =IFERROR(__xludf.DUMMYFUNCTION("""COMPUTED_VALUE"""),"SOPHIA JATOBÁ DOS SANTOS") | B30: =IFERROR(__xludf.DUMMYFUNCTION("""COMPUTED_VALUE"""),"Turma A") | C30: =IFERROR(__xludf.DUMMYFUNCTION("""COMPUTED_VALUE"""),"Vespertino") | D30: Veio | E30: ADULTO
A31: =IFERROR(__xludf.DUMMYFUNCTION("""COMPUTED_VALUE"""),"VICTOR EMANUEL ALMEIDA MARTINS") | B31: =IFERROR(__xludf.DUMMYFUNCTION("""COMPUTED_VALUE"""),"Turma B1") | C31: =IFERROR(__xludf.DUMMYFUNCTION("""COMPUTED_VALUE"""),"Vespertino") | D31: Veio | E31: PRÉ-INFANTIL

Sheet Categorias
A1: Categoria | B1: Turma | C1: Vitórias | D1: Empates | E1: Jogos Extras | F1: Atividades | G1: Grito de Guerra / Mascote / Bandeira | H1: Perdas | I1: Pontos | J1: Posição
A2: Infantil | B2: A m | C2: {=COUNTIF({Futebol!I:I; Futsal!I:I; Queimada!I:I; 'Rouba-Bandeira'!I:I}, B2)} | D2: {=SUMPRODUCT(({Futebol!I:I;Futsal!I:I;Queimada!I:I;'Rouba-Bandeira'!I:I}="Empate")*(({Futebol!H:H;Futsal!H:H;Queimada!H:H;'Rouba-Bandeira'!H:H}=$B2)+({Futebol!G:G;Futsal!G:G;Queimada!G:G;'Rouba-Bandeira'!G:G}=$B2)))} | E2: 0 | F2: Futebol Futsal Queimada Rouba-Bandeira | G2: 0 | H2: 0 | I2: =((C2*3) + (D2*1) + (E2*1) + G2) - H2 | J2: B1 m
B3: A v | C3: {=COUNTIF({Futebol!I:I; Futsal!I:I; Queimada!I:I; 'Rouba-Bandeira'!I:I}, B3)} | D3: {=SUMPRODUCT(({Futebol!I:I;Futsal!I:I;Queimada!I:I;'Rouba-Bandeira'!I:I}="Empate")*(({Futebol!H:H;Futsal!H:H;Queimada!H:H;'Rouba-Bandeira'!H:H}=$B3)+({Futebol!G:G;Futsal!G:G;Queimada!G:G;'Rouba-Bandeira'!G:G}=$B3)))} | E3: 3 | G3: 0 | H3: 1 | I3: =((C3*3) + (D3*1) + (E3*1) + G3) - H3
B4: B1 m | C4: {=COUNTIF({Futebol!I:I; Futsal!I:I; Queimada!I:I; 'Rouba-Bandeira'!I:I}, B4)} | D4: {=SUMPRODUCT(({Futebol!I:I;Futsal!I:I;Queimada!I:I;'Rouba-Bandeira'!I:I}="Empate")*(({Futebol!H:H;Futsal!H:H;Queimada!H:H;'Rouba-Bandeira'!H:H}=$B4)+({Futebol!G:G;Futsal!G:G;Queimada!G:G;'Rouba-Bandeira'!G:G}=$B4)))} | E4: 0 | G4: 3 | H4: 1 | I4: =((C4*3) + (D4*1) + (E4*1) + G4) - H4
B5: B1 v | C5: {=COUNTIF({Futebol!I:I; Futsal!I:I; Queimada!I:I; 'Rouba-Bandeira'!I:I}, B5)} | D5: {=SUMPRODUCT(({Futebol!I:I;Futsal!I:I;Queimada!I:I;'Rouba-Bandeira'!I:I}="Empate")*(({Futebol!H:H;Futsal!H:H;Queimada!H:H;'Rouba-Bandeira'!H:H}=$B5)+({Futebol!G:G;Futsal!G:G;Queimada!G:G;'Rouba-Bandeira'!G:G}=$B5)))} | E5: 0 | G5: 0 | H5: 1 | I5: =((C5*3) + (D5*1) + (E5*1) + G5) - H5
B6: B2 m | C6: {=COUNTIF({Futebol!I:I; Futsal!I:I; Queimada!I:I; 'Rouba-Bandeira'!I:I}, B6)} | D6: {=SUMPRODUCT(({Futebol!I:I;Futsal!I:I;Queimada!I:I;'Rouba-Bandeira'!I:I}="Empate")*(({Futebol!H:H;Futsal!H:H;Queimada!H:H;'Rouba-Bandeira'!H:H}=$B6)+({Futebol!G:G;Futsal!G:G;Queimada!G:G;'Rouba-Bandeira'!G:G}=$B6)))} | E6: 0 | G6: 0 | H6: 1 | I6: =((C6*3) + (D6*1) + (E6*1) + G6) - H6
A8: Juvenil | B8: B2 v | C8: {=COUNTIF({Futebol!I:I; Futsal!I:I; Queimada!I:I; 'Rouba-Bandeira'!I:I;Basquete!I:I}, B8)} | D8: {=SUMPRODUCT(({Futebol!I:I;Futsal!I:I;Queimada!I:I;'Rouba-Bandeira'!I:I;Basquete!I:I}="Empate")*(({Futebol!H:H;Futsal!H:H;Queimada!H:H;'Rouba-Bandeira'!H:H;Basquete!H:H}=$B8)+({Futebol!G:G;Futsal!G:G;Queimada!G:G;'Rouba-Bandeira'!G:G;Basquete!G:G}=$B8)))} | E8: 0 | F8: Futebol Futsal Queimada Rouba-Bandeira Basquete | G8: 0 | H8: 1 | I8: =((C8*3) + (D8*1) + (E8*1) + G8) - H8 | J8: D v
B9: C m | C9: {=COUNTIF({Futebol!I:I; Futsal!I:I; Queimada!I:I; 'Rouba-Bandeira'!I:I;Basquete!I:I}, B9)} | D9: {=SUMPRODUCT(({Futebol!I:I;Futsal!I:I;Queimada!I:I;'Rouba-Bandeira'!I:I;Basquete!I:I}="Empate")*(({Futebol!H:H;Futsal!H:H;Queimada!H:H;'Rouba-Bandeira'!H:H;Basquete!H:H}=$B9)+({Futebol!G:G;Futsal!G:G;Queimada!G:G;'Rouba-Bandeira'!G:G;Basquete!G:G}=$B9)))} | E9: 0 | G9: 0 | H9: 5 | I9: =((C9*3) + (D9*1) + (E9*1) + G9) - H9
B10: C v | C10: {=COUNTIF({Futebol!I:I; Futsal!I:I; Queimada!I:I; 'Rouba-Bandeira'!I:I;Basquete!I:I}, B10)} | D10: {=SUMPRODUCT(({Futebol!I:I;Futsal!I:I;Queimada!I:I;'Rouba-Bandeira'!I:I;Basquete!I:I}="Empate")*(({Futebol!H:H;Futsal!H:H;Queimada!H:H;'Rouba-Bandeira'!H:H;Basquete!H:H}=$B10)+({Futebol!G:G;Futsal!G:G;Queimada!G:G;'Rouba-Bandeira'!G:G;Basquete!G:G}=$B10)))} | E10: 0 | G10: 3 | H10: 1 | I10: =((C10*3) + (D10*1) + (E10*1) + G10) - H10
B11: D m | C11: {=COUNTIF({Futebol!I:I; Futsal!I:I; Queimada!I:I; 'Rouba-Bandeira'!I:I;Basquete!I:I}, B11)} | D11: {=SUMPRODUCT(({Futebol!I:I;Futsal!I:I;Queimada!I:I;'Rouba-Bandeira'!I:I;Basquete!I:I}="Empate")*(({Futebol!H:H;Futsal!H:H;Queimada!H:H;'Rouba-Bandeira'!H:H;Basquete!H:H}=$B11)+({Futebol!G:G;Futsal!G:G;Queimada!G:G;'Rouba-Bandeira'!G:G;Basquete!G:G}=$B11)))} | E11: 1 | G11: 0 | H11: 12 | I11: =((C11*3) + (D11*1) + (E11*1) + G11) - H11
B12: D v | C12: {=COUNTIF({Futebol!I:I; Futsal!I:I; Queimada!I:I; 'Rouba-Bandeira'!I:I;Basquete!I:I}, B12)} | D12: {=SUMPRODUCT(({Futebol!I:I;Futsal!I:I;Queimada!I:I;'Rouba-Bandeira'!I:I;Basquete!I:I}="Empate")*(({Futebol!H:H;Futsal!H:H;Queimada!H:H;'Rouba-Bandeira'!H:H;Basquete!H:H}=$B12)+({Futebol!G:G;Futsal!G:G;Queimada!G:G;'Rouba-Bandeira'!G:G;Basquete!G:G}=$B12)))} | E12: 1 | G12: 0 | H12: 4 | I12: =((C12*3) + (D12*1) + (E12*1) + G12) - H12
A14: Júnior | B14: E m | C14: {=COUNTIF({Futebol!I:I; Futsal!I:I; Queimada!I:I; 'Rouba-Bandeira'!I:I;Basquete!I:I;'Volêi'!I:I}, B14)} | D14: {=SUMPRODUCT(({Futebol!I:I;Futsal!I:I;Queimada!I:I;'Rouba-Bandeira'!I:I;Basquete!I:I;'Volêi'!I:I}="Empate")*(({Futebol!H:H;Futsal!H:H;Queimada!H:H;'Rouba-Bandeira'!H:H;Basquete!H:H;'Volêi'!H:H}=$B14)+({Futebol!G:G;Futsal!G:G;Queimada!G:G;'Rouba-Bandeira'!G:G;Basquete!G:G;'Volêi'!G:G}=$B14)))} | E14: 0 | F14: Futebol Futsal Queimada Rouba-Bandeira Basquete Vôlei | G14: 0 | H14: 1 | I14: =((C14*3) + (D14*1) + (E14*1) + G14) - H14 | J14: E m
B15: E v | C15: {=COUNTIF({Futebol!I:I; Futsal!I:I; Queimada!I:I; 'Rouba-Bandeira'!I:I;Basquete!I:I;'Volêi'!I:I}, B15)} | D15: {=SUMPRODUCT(({Futebol!I:I;Futsal!I:I;Queimada!I:I;'Rouba-Bandeira'!I:I;Basquete!I:I;'Volêi'!I:I}="Empate")*(({Futebol!H:H;Futsal!H:H;Queimada!H:H;'Rouba-Bandeira'!H:H;Basquete!H:H;'Volêi'!H:H}=$B15)+({Futebol!G:G;Futsal!G:G;Queimada!G:G;'Rouba-Bandeira'!G:G;Basquete!G:G;'Volêi'!G:G}=$B15)))} | E15: 3 | G15: 0 | H15: 1 | I15: =((C15*3) + (D15*1) + (E15*1) + G15) - H15
B16: GR | C16: {=COUNTIF({Futebol!I:I; Futsal!I:I; Queimada!I:I; 'Rouba-Bandeira'!I:I;Basquete!I:I;'Volêi'!I:I}, B16)} | D16: {=SUMPRODUCT(({Futebol!I:I;Futsal!I:I;Queimada!I:I;'Rouba-Bandeira'!I:I;Basquete!I:I;'Volêi'!I:I}="Empate")*(({Futebol!H:H;Futsal!H:H;Queimada!H:H;'Rouba-Bandeira'!H:H;Basquete!H:H;'Volêi'!H:H}=$B16)+({Futebol!G:G;Futsal!G:G;Queimada!G:G;'Rouba-Bandeira'!G:G;Basquete!G:G;'Volêi'!G:G}=$B16)))} | E16: 0 | G16: 3 | H16: 2 | I16: =((C16*3) + (D16*1) + (E16*1) + G16) - H16

Sheet Futebol
A1: Competidores | B1: Turma | C1: Período | D1: Presente | F1: CONFRONTOS
A2: =IFERROR(__xludf.DUMMYFUNCTION("FILTER(Alunos!A:A, Alunos!$D:$D = ""Participa"")"),"ADILSON EVÊNCIO DA SILVA JUNIOR") | B2: =IFERROR(__xludf.DUMMYFUNCTION("FILTER(Alunos!B:B, Alunos!$D:$D = ""Participa"")"),"Turma E") | C2: =IFERROR(__xludf.DUMMYFUNCTION("FILTER(Alunos!C:C, Alunos!$D:$D = ""Participa"")"),"Matutino") | D2: Veio | F2: Categoria | G2: Turmas | I2: Resultados
A3: =IFERROR(__xludf.DUMMYFUNCTION("""COMPUTED_VALUE"""),"ALIPHER GABRIEL LOPES FERREIRA") | B3: =IFERROR(__xludf.DUMMYFUNCTION("""COMPUTED_VALUE"""),"Turma B2") | C3: =IFERROR(__xludf.DUMMYFUNCTION("""COMPUTED_VALUE"""),"Vespertino") | D3: Não Veio | F3: Infantil | G3: A v | H3: B2 m | I3: A v
A4: =IFERROR(__xludf.DUMMYFUNCTION("""COMPUTED_VALUE"""),"ALLAN ALVES RIBEIRO") | B4: =IFERROR(__xludf.DUMMYFUNCTION("""COMPUTED_VALUE"""),"Turma E") | C4: =IFERROR(__xludf.DUMMYFUNCTION("""COMPUTED_VALUE"""),"Vespertino") | D4: Veio | G4: B1 m | H4: B1 v | I4: B1 m
A5: =IFERROR(__xludf.DUMMYFUNCTION("""COMPUTED_VALUE"""),"Allana Gonçalves Da Silva") | B5: =IFERROR(__xludf.DUMMYFUNCTION("""COMPUTED_VALUE"""),"Turma C") | C5: =IFERROR(__xludf.DUMMYFUNCTION("""COMPUTED_VALUE"""),"Matutino") | D5: Veio | G5: A m | H5: B2 m | I5: A m
A6: =IFERROR(__xludf.DUMMYFUNCTION("""COMPUTED_VALUE"""),"ANA CLARA DE FREITAS TEIXEIRA") | B6: =IFERROR(__xludf.DUMMYFUNCTION("""COMPUTED_VALUE"""),"Turma GR") | C6: =IFERROR(__xludf.DUMMYFUNCTION("""COMPUTED_VALUE"""),"Vespertino") | D6: Veio | G6: A v | H6: B1 m | I6: B1 m
A7: =IFERROR(__xludf.DUMMYFUNCTION("""COMPUTED_VALUE"""),"ANA CRISTINA SOUZA LOBAK") | B7: =IFERROR(__xludf.DUMMYFUNCTION("""COMPUTED_VALUE"""),"Turma E") | C7: =IFERROR(__xludf.DUMMYFUNCTION("""COMPUTED_VALUE"""),"Vespertino") | D7: Veio | G7: A m | H7: B1 v | I7: B1 v
A8: =IFERROR(__xludf.DUMMYFUNCTION("""COMPUTED_VALUE"""),"Ana Julia Da Cruz Oliveira") | B8: =IFERROR(__xludf.DUMMYFUNCTION("""COMPUTED_VALUE"""),"Turma A") | C8: =IFERROR(__xludf.DUMMYFUNCTION("""COMPUTED_VALUE"""),"Matutino") | D8: Veio | G8: B2 m | H8: B1 m | I8: B1 m
A9: =IFERROR(__xludf.DUMMYFUNCTION("""COMPUTED_VALUE"""),"ANA LUIZA DA SILVA BORGES") | B9: =IFERROR(__xludf.DUMMYFUNCTION("""COMPUTED_VALUE"""),"Turma E") | C9: =IFERROR(__xludf.DUMMYFUNCTION("""COMPUTED_VALUE"""),"Matutino") | D9: Veio | G9: A m | H9: B1 m | I9: B1 m
A10: =IFERROR(__xludf.DUMMYFUNCTION("""COMPUTED_VALUE"""),"Ana Vitória Santana Oliveira Da Silva") | B10: =IFERROR(__xludf.DUMMYFUNCTION("""COMPUTED_VALUE"""),"Turma A") | C10: =IFERROR(__xludf.DUMMYFUNCTION("""COMPUTED_VALUE"""),"Matutino") | D10: Veio | G10: B1 v | H10: A v | I10: B1 v
A11: =IFERROR(__xludf.DUMMYFUNCTION("""COMPUTED_VALUE"""),"Andressa Campos De Barros") | B11: =IFERROR(__xludf.DUMMYFUNCTION("""COMPUTED_VALUE"""),"Turma D") | C11: =IFERROR(__xludf.DUMMYFUNCTION("""COMPUTED_VALUE"""),"Vespertino") | D11: Veio | G11: A m | H11: A v | I11: A v
A12: =IFERROR(__xludf.DUMMYFUNCTION("""COMPUTED_VALUE"""),"ANNY HELOISE OLIVEIRA DA SILVA") | B12: =IFERROR(__xludf.DUMMYFUNCTION("""COMPUTED_VALUE"""),"Turma B2") | C12: =IFERROR(__xludf.DUMMYFUNCTION("""COMPUTED_VALUE"""),"Vespertino") | D12: Veio | G12: B1 v | H12: B2 m | I12: B1 v
A13: =IFERROR(__xludf.DUMMYFUNCTION("""COMPUTED_VALUE"""),"AQUIRIZ ARAUJO DE FREITAS") | B13: =IFERROR(__xludf.DUMMYFUNCTION("""COMPUTED_VALUE"""),"Turma C") | C13: =IFERROR(__xludf.DUMMYFUNCTION("""COMPUTED_VALUE"""),"Vespertino") | D13: Veio | F13: Juvenil | G13: C m | H13: D v | I13: D v
A14: =IFERROR(__xludf.DUMMYFUNCTION("""COMPUTED_VALUE"""),"ARTHUR ALMEIDA JATOBÁ") | B14: =IFERROR(__xludf.DUMMYFUNCTION("""COMPUTED_VALUE"""),"Turma B2") | C14: =IFERROR(__xludf.DUMMYFUNCTION("""COMPUTED_VALUE"""),"Matutino") | D14: Veio | G14: C v | H14: D m | I14: D m
A15: =IFERROR(__xludf.DUMMYFUNCTION("""COMPUTED_VALUE"""),"ARTHUR FERREIRA NAPOLEÃO") | B15: =IFERROR(__xludf.DUMMYFUNCTION("""COMPUTED_VALUE"""),"Turma D") | C15: =IFERROR(__xludf.DUMMYFUNCTION("""COMPUTED_VALUE"""),"Matutino") | D15: Veio | G15: B2 v | H15: D v | I15: D v
A16: =IFERROR(__xludf.DUMMYFUNCTION("""COMPUTED_VALUE"""),"ARTHUR LOPES RODRIGUES NEVES") | B16: =IFERROR(__xludf.DUMMYFUNCTION("""COMPUTED_VALUE"""),"Turma B2") | C16: =IFERROR(__xludf.DUMMYFUNCTION("""COMPUTED_VALUE"""),"Vespertino") | D16: Veio | G16: C m | H16: C v | I16: C v
A17: =IFERROR(__xludf.DUMMYFUNCTION("""COMPUTED_VALUE"""),"ARTHUR SANTANA BARBOSA") | B17: =IFERROR(__xludf.DUMMYFUNCTION("""COMPUTED_VALUE"""),"Turma A") | C17: =IFERROR(__xludf.DUMMYFUNCTION("""COMPUTED_VALUE"""),"Vespertino") | D17: Veio | G17: B2 v | H17: D m | I17: D m
A18: =IFERROR(__xludf.DUMMYFUNCTION("""COMPUTED_VALUE"""),"ASAPH GABRIEL SALES ANICETO") | B18: =IFERROR(__xludf.DUMMYFUNCTION("""COMPUTED_VALUE"""),"Turma B2") | C18: =IFERROR(__xludf.DUMMYFUNCTION("""COMPUTED_VALUE"""),"Matutino") | D18: Veio | G18: D v | H18: C v | I18: D v
A19: =IFERROR(__xludf.DUMMYFUNCTION("""COMPUTED_VALUE"""),"Breno Henrique Germano Dos Santos") | B19: =IFERROR(__xludf.DUMMYFUNCTION("""COMPUTED_VALUE"""),"Turma C") | C19: =IFERROR(__xludf.DUMMYFUNCTION("""COMPUTED_VALUE"""),"Matutino") | D19: Veio | G19: B2 v | H19: C v | I19: Empate
A20: =IFERROR(__xludf.DUMMYFUNCTION("""COMPUTED_VALUE"""),"CAIO RUAN GERÔNIMO OLIVEIRA") | B20: =IFERROR(__xludf.DUMMYFUNCTION("""COMPUTED_VALUE"""),"Turma E") | C20: =IFERROR(__xludf.DUMMYFUNCTION("""COMPUTED_VALUE"""),"Matutino") | D20: Veio | G20: D m | H20: C m | I20: D m
A21: =IFERROR(__xludf.DUMMYFUNCTION("""COMPUTED_VALUE"""),"CAIO SOUZA PRÓCÓPIO DA SILVA") | B21: =IFERROR(__xludf.DUMMYFUNCTION("""COMPUTED_VALUE"""),"Turma E") | C21: =IFERROR(__xludf.DUMMYFUNCTION("""COMPUTED_VALUE"""),"Matutino") | D21: Veio | G21: B2 v | H21: C m | I21: Empate
A22: =IFERROR(__xludf.DUMMYFUNCTION("""COMPUTED_VALUE"""),"CARLOS DANIEL BARROSO FERREIRA") | B22: =IFERROR(__xludf.DUMMYFUNCTION("""COMPUTED_VALUE"""),"Turma C") | C22: =IFERROR(__xludf.DUMMYFUNCTION("""COMPUTED_VALUE"""),"Vespertino") | D22: Veio | G22: D m | H22: D v | I22: Empate
A23: =IFERROR(__xludf.DUMMYFUNCTION("""COMPUTED_VALUE"""),"Carlos Eduardo De Souza") | B23: =IFERROR(__xludf.DUMMYFUNCTION("""COMPUTED_VALUE"""),"Turma D") | C23: =IFERROR(__xludf.DUMMYFUNCTION("""COMPUTED_VALUE"""),"Vespertino") | D23: Veio | F23: Júnior | G23: E m | H23: E v | I23: E m
A24: =IFERROR(__xludf.DUMMYFUNCTION("""COMPUTED_VALUE"""),"CARLOS EDUARDO GENUINO DE ALENCAR") | B24: =IFERROR(__xludf.DUMMYFUNCTION("""COMPUTED_VALUE"""),"Turma C") | C24: =IFERROR(__xludf.DUMMYFUNCTION("""COMPUTED_VALUE"""),"Vespertino") | D24: Veio | G24: GR | H24: E m | I24: Empate
A25: =IFERROR(__xludf.DUMMYFUNCTION("""COMPUTED_VALUE"""),"CAUÃ SOUZA PROCÓPIO DA SILVA") | B25: =IFERROR(__xludf.DUMMYFUNCTION("""COMPUTED_VALUE"""),"Turma A") | C25: =IFERROR(__xludf.DUMMYFUNCTION("""COMPUTED_VALUE"""),"Vespertino") | D25: Veio | G25: E v | H25: GR | I25: E v
A26: =IFERROR(__xludf.DUMMYFUNCTION("""COMPUTED_VALUE"""),"CAUÃ VITORINO HOTTS DA SILVA") | B26: =IFERROR(__xludf.DUMMYFUNCTION("""COMPUTED_VALUE"""),"Turma E") | C26: =IFERROR(__xludf.DUMMYFUNCTION("""COMPUTED_VALUE"""),"Vespertino") | D26: Veio
A27: =IFERROR(__xludf.DUMMYFUNCTION("""COMPUTED_VALUE"""),"CLAUDIA GABRIELY CAMARGO MOREIRA") | B27: =IFERROR(__xludf.DUMMYFUNCTION("""COMPUTED_VALUE"""),"Turma D") | C27: =IFERROR(__xludf.DUMMYFUNCTION("""COMPUTED_VALUE"""),"Matutino") | D27: Veio
A28: =IFERROR(__xludf.DUMMYFUNCTION("""COMPUTED_VALUE"""),"Daffiny De Jesus Silva") | B28: =IFERROR(__xludf.DUMMYFUNCTION("""COMPUTED_VALUE"""),"Turma A") | C28: =IFERROR(__xludf.DUMMYFUNCTION("""COMPUTED_VALUE"""),"Matutino") | D28: Veio
A29: =IFERROR(__xludf.DUMMYFUNCTION("""COMPUTED_VALUE"""),"DANIEL VIEIRA MARTINS") | B29: =IFERROR(__xludf.DUMMYFUNCTION("""COMPUTED_VALUE"""),"Turma B1") | C29: =IFERROR(__xludf.DUMMYFUNCTION("""COMPUTED_VALUE"""),"Matutino") | D29: Veio
A30: =IFERROR(__xludf.DUMMYFUNCTION("""COMPUTED_VALUE"""),"Danielly Hilary Almeida Martins") | B30: =IFERROR(__xludf.DUMMYFUNCTION("""COMPUTED_VALUE"""),"Turma D") | C30: =IFERROR(__xludf.DUMMYFUNCTION("""COMPUTED_VALUE"""),"Vespertino") | D30: Veio
A31: =IFERROR(__xludf.DUMMYFUNCTION("""COMPUTED_VALUE"""),"Darlan Guilherme Sobreiro Romero Da Silva") | B31: =IFERROR(__xludf.DUMMYFUNCTION("""COMPUTED_VALUE"""),"Turma D") | C31: =IFERROR(__xludf.DUMMYFUNCTION("""COMPUTED_VALUE"""),"Vespertino") | D31: Veio
A32: =IFERROR(__xludf.DUMMYFUNCTION("""COMPUTED_VALUE"""),"DAVI LORENZO BARBOSA MOREIRA") | B32: =IFERROR(__xludf.DUMMYFUNCTION("""COMPUTED_VALUE"""),"Turma C") | C32: =IFERROR(__xludf.DUMMYFUNCTION("""COMPUTED_VALUE"""),"Vespertino") | D32: Veio
A33: =IFERROR(__xludf.DUMMYFUNCTION("""COMPUTED_VALUE"""),"DAVI LUCAS ALVES DE SOUZA") | B33: =IFERROR(__xludf.DUMMYFUNCTION("""COMPUTED_VALUE"""),"Turma B1") | C33: =IFERROR(__xludf.DUMMYFUNCTION("""COMPUTED_VALUE"""),"Matutino") | D33: Veio
A34: =IFERROR(__xludf.DUMMYFUNCTION("""COMPUTED_VALUE"""),"DAVI LUCAS DE LIMA TRINDADE") | B34: =IFERROR(__xludf.DUMMYFUNCTION("""COMPUTED_VALUE"""),"Turma C") | C34: =IFERROR(__xludf.DUMMYFUNCTION("""COMPUTED_VALUE"""),"Vespertino") | D34: Veio
A35: =IFERROR(__xludf.DUMMYFUNCTION("""COMPUTED_VALUE"""),"David William Pimenta Menezes") | B35: =IFERROR(__xludf.DUMMYFUNCTION("""COMPUTED_VALUE"""),"Turma D") | C35: =IFERROR(__xludf.DUMMYFUNCTION("""COMPUTED_VALUE"""),"Vespertino") | D35: Veio
A36: =IFERROR(__xludf.DUMMYFUNCTION("""COMPUTED_VALUE"""),"DAVY CAMPOS BARROS") | B36: =IFERROR(__xludf.DUMMYFUNCTION("""COMPUTED_VALUE"""),"Turma A") | C36: =IFERROR(__xludf.DUMMYFUNCTION("""COMPUTED_VALUE"""),"Vespertino") | D36: Veio
A37: =IFERROR(__xludf.DUMMYFUNCTION("""COMPUTED_VALUE"""),"DAVY THAYLOM OLIVEIRA DOS SANTOS") | B37: =IFERROR(__xludf.DUMMYFUNCTION("""COMPUTED_VALUE"""),"Turma A") | C37: =IFERROR(__xludf.DUMMYFUNCTION("""COMPUTED_VALUE"""),"Vespertino") | D37: Veio
A38: =IFERROR(__xludf.DUMMYFUNCTION("""COMPUTED_VALUE"""),"DERIK PEREIRA VIANA") | B38: =IFERROR(__xludf.DUMMYFUNCTION("""COMPUTED_VALUE"""),"Turma B2") | C38: =IFERROR(__xludf.DUMMYFUNCTION("""COMPUTED_VALUE"""),"Vespertino") | D38: Veio
A39: =IFERROR(__xludf.DUMMYFUNCTION("""COMPUTED_VALUE"""),"DIEGO MARQUES SOUZA DA SILVA") | B39: =IFERROR(__xludf.DUMMYFUNCTION("""COMPUTED_VALUE"""),"Turma E") | C39: =IFERROR(__xludf.DUMMYFUNCTION("""COMPUTED_VALUE"""),"Matutino") | D39: Veio
A40: =IFERROR(__xludf.DUMMYFUNCTION("""COMPUTED_VALUE"""),"DIEGO RENAN OLIVEIRA DA SILVA") | B40: =IFERROR(__xludf.DUMMYFUNCTION("""COMPUTED_VALUE"""),"Turma E") | C40: =IFERROR(__xludf.DUMMYFUNCTION("""COMPUTED_VALUE"""),"Vespertino") | D40: Veio
...

Sheet Futsal
A1: Competidores | B1: Turma | C1: Período | D1: Presente | F1: CONFRONTOS
A2: =IFERROR(__xludf.DUMMYFUNCTION("FILTER(Alunos!A:A, Alunos!$E:$E = ""Participa"")"),"ADILSON EVÊNCIO DA SILVA JUNIOR") | B2: =IFERROR(__xludf.DUMMYFUNCTION("FILTER(Alunos!B:B, Alunos!$E:$E = ""Participa"")"),"Turma E") | C2: =IFERROR(__xludf.DUMMYFUNCTION("FILTER(Alunos!C:C, Alunos!$E:$E = ""Participa"")"),"Matutino") | D2: Veio | F2: Categoria | G2: Turmas | I2: Resultados
A3: =IFERROR(__xludf.DUMMYFUNCTION("""COMPUTED_VALUE"""),"ALIPHER GABRIEL LOPES FERREIRA") | B3: =IFERROR(__xludf.DUMMYFUNCTION("""COMPUTED_VALUE"""),"Turma B2") | C3: =IFERROR(__xludf.DUMMYFUNCTION("""COMPUTED_VALUE"""),"Vespertino") | D3: Veio | F3: Infantil | G3: A v | H3: B2 m | I3: A v
A4: =IFERROR(__xludf.DUMMYFUNCTION("""COMPUTED_VALUE"""),"ALLAN ALVES RIBEIRO") | B4: =IFERROR(__xludf.DUMMYFUNCTION("""COMPUTED_VALUE"""),"Turma E") | C4: =IFERROR(__xludf.DUMMYFUNCTION("""COMPUTED_VALUE"""),"Vespertino") | D4: Veio | G4: B1 m | H4: B1 v | I4: B1 m
A5: =IFERROR(__xludf.DUMMYFUNCTION("""COMPUTED_VALUE"""),"ANA CLARA DE FREITAS TEIXEIRA") | B5: =IFERROR(__xludf.DUMMYFUNCTION("""COMPUTED_VALUE"""),"Turma GR") | C5: =IFERROR(__xludf.DUMMYFUNCTION("""COMPUTED_VALUE"""),"Vespertino") | D5: Veio | G5: A m | H5: B2 m | I5: Empate
A6: =IFERROR(__xludf.DUMMYFUNCTION("""COMPUTED_VALUE"""),"ANA CRISTINA SOUZA LOBAK") | B6: =IFERROR(__xludf.DUMMYFUNCTION("""COMPUTED_VALUE"""),"Turma E") | C6: =IFERROR(__xludf.DUMMYFUNCTION("""COMPUTED_VALUE"""),"Vespertino") | D6: Veio | G6: A v | H6: B1 m | I6: Empate | J6: Aluno (n/d) b1 m
A7: =IFERROR(__xludf.DUMMYFUNCTION("""COMPUTED_VALUE"""),"ANA LUIZA DA SILVA BORGES") | B7: =IFERROR(__xludf.DUMMYFUNCTION("""COMPUTED_VALUE"""),"Turma E") | C7: =IFERROR(__xludf.DUMMYFUNCTION("""COMPUTED_VALUE"""),"Matutino") | D7: Veio | G7: A m | H7: B1 v | I7: B1 v
A8: =IFERROR(__xludf.DUMMYFUNCTION("""COMPUTED_VALUE"""),"Andressa Campos De Barros") | B8: =IFERROR(__xludf.DUMMYFUNCTION("""COMPUTED_VALUE"""),"Turma D") | C8: =IFERROR(__xludf.DUMMYFUNCTION("""COMPUTED_VALUE"""),"Vespertino") | D8: Veio | G8: B2 m | H8: B1 m | I8: B1 m
A9: =IFERROR(__xludf.DUMMYFUNCTION("""COMPUTED_VALUE"""),"ANNY HELOISE OLIVEIRA DA SILVA") | B9: =IFERROR(__xludf.DUMMYFUNCTION("""COMPUTED_VALUE"""),"Turma B2") | C9: =IFERROR(__xludf.DUMMYFUNCTION("""COMPUTED_VALUE"""),"Vespertino") | D9: Veio | G9: A m | H9: B1 m | I9: B1 m | J9: Aluno (n/d) turma C m
A10: =IFERROR(__xludf.DUMMYFUNCTION("""COMPUTED_VALUE"""),"AQUIRIZ ARAUJO DE FREITAS") | B10: =IFERROR(__xludf.DUMMYFUNCTION("""COMPUTED_VALUE"""),"Turma C") | C10: =IFERROR(__xludf.DUMMYFUNCTION("""COMPUTED_VALUE"""),"Vespertino") | D10: Veio | G10: B1 v | H10: A v | I10: Empate | J10: Aluno 049 D v
A11: =IFERROR(__xludf.DUMMYFUNCTION("""COMPUTED_VALUE"""),"ARTHUR FERREIRA NAPOLEÃO") | B11: =IFERROR(__xludf.DUMMYFUNCTION("""COMPUTED_VALUE"""),"Turma D") | C11: =IFERROR(__xludf.DUMMYFUNCTION("""COMPUTED_VALUE"""),"Matutino") | D11: Veio | G11: A m | H11: A v | I11: A v | J11: Aluno (n/d) D m
A12: =IFERROR(__xludf.DUMMYFUNCTION("""COMPUTED_VALUE"""),"ARTHUR LOPES RODRIGUES NEVES") | B12: =IFERROR(__xludf.DUMMYFUNCTION("""COMPUTED_VALUE"""),"Turma B2") | C12: =IFERROR(__xludf.DUMMYFUNCTION("""COMPUTED_VALUE"""),"Vespertino") | D12: Veio | G12: B1 v | H12: B2 m | I12: B1 v
A13: =IFERROR(__xludf.DUMMYFUNCTION("""COMPUTED_VALUE"""),"ARTHUR SANTANA BARBOSA") | B13: =IFERROR(__xludf.DUMMYFUNCTION("""COMPUTED_VALUE"""),"Turma A") | C13: =IFERROR(__xludf.DUMMYFUNCTION("""COMPUTED_VALUE"""),"Vespertino") | D13: Veio | F13: Juvenil | G13: C m | H13: D v | I13: D v | K13: Aluno (n/d) D v expulso (individual)
